20:33:35 - mtprotosender
[INFO] _connect:
 226 - Connecting to 149.154.167.51:443/TcpFull...
20:33:35 - mtprotosender
[INFO] _connect:
 277 - Connection to 149.154.167.51:443/TcpFull complete!
20:33:36 - __init__
[INFO] autodetect:
 49 - file_cache is only supported with oauth2client<4.0.0
20:33:39 - tele
[ERROR] run:
 148 - Traceback (most recent call last):
  File "c:\MyWork\Orders\InstaTeleAnalyzer\tools\tele.py", line 144, in run
    self.collect_msgs_from_channels()
  File "c:\MyWork\Orders\InstaTeleAnalyzer\tools\tele.py", line 122, in collect_msgs_from_channels
    with client:
  File "C:\MyWork\Orders\InstaTeleAnalyzer\Lib\site-packages\telethon\helpers.py", line 208, in _sync_enter
    if hasattr(self, 'loop'):
       ^^^^^^^^^^^^^^^^^^^^^
  File "C:\MyWork\Orders\InstaTeleAnalyzer\Lib\site-packages\telethon\client\telegrambaseclient.py", line 473, in loop
    return asyncio.get_event_loop()
           ^^^^^^^^^^^^^^^^^^^^^^^^
  File "C:\Users\pepega\AppData\Local\Programs\Python\Python311\Lib\asyncio\events.py", line 677, in get_event_loop
    raise RuntimeError('There is no current event loop in thread %r.'
RuntimeError: There is no current event loop in thread 'Thread-2'.

